[2024-08-04T12:58:48.096+0000] {local_task_job_runner.py:120} INFO - ::group::Pre task execution logs
[2024-08-04T12:58:48.118+0000] {taskinstance.py:2076} INFO - Dependencies all met for dep_context=non-requeueable deps ti=<TaskInstance: export_multiple_dbs_to_s3_dag.extract_and_upload_orders scheduled__2024-08-03T00:00:00+00:00 [queued]>
[2024-08-04T12:58:48.125+0000] {taskinstance.py:2076} INFO - Dependencies all met for dep_context=requeueable deps ti=<TaskInstance: export_multiple_dbs_to_s3_dag.extract_and_upload_orders scheduled__2024-08-03T00:00:00+00:00 [queued]>
[2024-08-04T12:58:48.127+0000] {taskinstance.py:2306} INFO - Starting attempt 2 of 3
[2024-08-04T12:58:48.141+0000] {taskinstance.py:2330} INFO - Executing <Task(PythonOperator): extract_and_upload_orders> on 2024-08-03 00:00:00+00:00
[2024-08-04T12:58:48.147+0000] {warnings.py:112} WARNING - /home/***/.local/lib/python3.12/site-packages/***/task/task_runner/standard_task_runner.py:62: DeprecationWarning: This process (pid=176) is multi-threaded, use of fork() may lead to deadlocks in the child.
  pid = os.fork()

[2024-08-04T12:58:48.148+0000] {standard_task_runner.py:64} INFO - Started process 178 to run task
[2024-08-04T12:58:48.149+0000] {standard_task_runner.py:90} INFO - Running: ['***', 'tasks', 'run', 'export_multiple_dbs_to_s3_dag', 'extract_and_upload_orders', 'scheduled__2024-08-03T00:00:00+00:00', '--job-id', '161', '--raw', '--subdir', 'DAGS_FOLDER/export_multiple_dbs_to_s3_dag .py', '--cfg-path', '/tmp/tmpihc8blcd']
[2024-08-04T12:58:48.150+0000] {standard_task_runner.py:91} INFO - Job 161: Subtask extract_and_upload_orders
[2024-08-04T12:58:48.219+0000] {task_command.py:426} INFO - Running <TaskInstance: export_multiple_dbs_to_s3_dag.extract_and_upload_orders scheduled__2024-08-03T00:00:00+00:00 [running]> on host 715fe0bea338
[2024-08-04T12:58:48.300+0000] {taskinstance.py:2648} INFO - Exporting env vars: AIRFLOW_CTX_DAG_OWNER='***' AIRFLOW_CTX_DAG_ID='export_multiple_dbs_to_s3_dag' AIRFLOW_CTX_TASK_ID='extract_and_upload_orders' AIRFLOW_CTX_EXECUTION_DATE='2024-08-03T00:00:00+00:00' AIRFLOW_CTX_TRY_NUMBER='2' AIRFLOW_CTX_DAG_RUN_ID='scheduled__2024-08-03T00:00:00+00:00'
[2024-08-04T12:58:48.302+0000] {taskinstance.py:430} INFO - ::endgroup::
[2024-08-04T12:58:48.323+0000] {taskinstance.py:441} INFO - ::group::Post task execution logs
[2024-08-04T12:58:48.324+0000] {taskinstance.py:2905} ERROR - Task failed with exception
Traceback (most recent call last):
  File "/home/airflow/.local/lib/python3.12/site-packages/airflow/models/taskinstance.py", line 465, in _execute_task
    result = _execute_callable(context=context, **execute_callable_kwargs)
             ^^^^^^^^^^^^^^^^^^^^^^^^^^^^^^^^^^^^^^^^^^^^^^^^^^^^^^^^^^^^^
  File "/home/airflow/.local/lib/python3.12/site-packages/airflow/models/taskinstance.py", line 432, in _execute_callable
    return execute_callable(context=context, **execute_callable_kwargs)
           ^^^^^^^^^^^^^^^^^^^^^^^^^^^^^^^^^^^^^^^^^^^^^^^^^^^^^^^^^^^^
  File "/home/airflow/.local/lib/python3.12/site-packages/airflow/models/baseoperator.py", line 401, in wrapper
    return func(self, *args, **kwargs)
           ^^^^^^^^^^^^^^^^^^^^^^^^^^^
  File "/home/airflow/.local/lib/python3.12/site-packages/airflow/operators/python.py", line 235, in execute
    return_value = self.execute_callable()
                   ^^^^^^^^^^^^^^^^^^^^^^^
  File "/home/airflow/.local/lib/python3.12/site-packages/airflow/operators/python.py", line 252, in execute_callable
    return self.python_callable(*self.op_args, **self.op_kwargs)
           ^^^^^^^^^^^^^^^^^^^^^^^^^^^^^^^^^^^^^^^^^^^^^^^^^^^^^
  File "/opt/airflow/dags/export_multiple_dbs_to_s3_dag .py", line 28, in extract_and_upload_to_s3
    s3_client.put_object(Bucket=s3_bucket, Key=s3_key, Body=csv_buffer.getvalue())
  File "/home/airflow/.local/lib/python3.12/site-packages/botocore/client.py", line 565, in _api_call
    return self._make_api_call(operation_name, kwargs)
           ^^^^^^^^^^^^^^^^^^^^^^^^^^^^^^^^^^^^^^^^^^^
  File "/home/airflow/.local/lib/python3.12/site-packages/botocore/client.py", line 1001, in _make_api_call
    http, parsed_response = self._make_request(
                            ^^^^^^^^^^^^^^^^^^^
  File "/home/airflow/.local/lib/python3.12/site-packages/botocore/client.py", line 1027, in _make_request
    return self._endpoint.make_request(operation_model, request_dict)
           ^^^^^^^^^^^^^^^^^^^^^^^^^^^^^^^^^^^^^^^^^^^^^^^^^^^^^^^^^^
  File "/home/airflow/.local/lib/python3.12/site-packages/botocore/endpoint.py", line 119, in make_request
    return self._send_request(request_dict, operation_model)
           ^^^^^^^^^^^^^^^^^^^^^^^^^^^^^^^^^^^^^^^^^^^^^^^^^
  File "/home/airflow/.local/lib/python3.12/site-packages/botocore/endpoint.py", line 198, in _send_request
    request = self.create_request(request_dict, operation_model)
              ^^^^^^^^^^^^^^^^^^^^^^^^^^^^^^^^^^^^^^^^^^^^^^^^^^
  File "/home/airflow/.local/lib/python3.12/site-packages/botocore/endpoint.py", line 134, in create_request
    self._event_emitter.emit(
  File "/home/airflow/.local/lib/python3.12/site-packages/botocore/hooks.py", line 412, in emit
    return self._emitter.emit(aliased_event_name, **kwargs)
           ^^^^^^^^^^^^^^^^^^^^^^^^^^^^^^^^^^^^^^^^^^^^^^^^
  File "/home/airflow/.local/lib/python3.12/site-packages/botocore/hooks.py", line 256, in emit
    return self._emit(event_name, kwargs)
           ^^^^^^^^^^^^^^^^^^^^^^^^^^^^^^
  File "/home/airflow/.local/lib/python3.12/site-packages/botocore/hooks.py", line 239, in _emit
    response = handler(**kwargs)
               ^^^^^^^^^^^^^^^^^
  File "/home/airflow/.local/lib/python3.12/site-packages/botocore/signers.py", line 105, in handler
    return self.sign(operation_name, request)
           ^^^^^^^^^^^^^^^^^^^^^^^^^^^^^^^^^^
  File "/home/airflow/.local/lib/python3.12/site-packages/botocore/signers.py", line 199, in sign
    auth.add_auth(request)
  File "/home/airflow/.local/lib/python3.12/site-packages/botocore/auth.py", line 418, in add_auth
    raise NoCredentialsError()
botocore.exceptions.NoCredentialsError: Unable to locate credentials
[2024-08-04T12:58:48.337+0000] {taskinstance.py:1206} INFO - Marking task as UP_FOR_RETRY. dag_id=export_multiple_dbs_to_s3_dag, task_id=extract_and_upload_orders, run_id=scheduled__2024-08-03T00:00:00+00:00, execution_date=20240803T000000, start_date=20240804T125848, end_date=20240804T125848
[2024-08-04T12:58:48.351+0000] {standard_task_runner.py:110} ERROR - Failed to execute job 161 for task extract_and_upload_orders (Unable to locate credentials; 178)
[2024-08-04T12:58:48.362+0000] {local_task_job_runner.py:243} INFO - Task exited with return code 1
[2024-08-04T12:58:48.384+0000] {taskinstance.py:3503} INFO - 0 downstream tasks scheduled from follow-on schedule check
[2024-08-04T12:58:48.387+0000] {local_task_job_runner.py:222} INFO - ::endgroup::
