[2024-08-04T13:12:12.198+0000] {local_task_job_runner.py:120} INFO - ::group::Pre task execution logs
[2024-08-04T13:12:12.231+0000] {taskinstance.py:2076} INFO - Dependencies all met for dep_context=non-requeueable deps ti=<TaskInstance: export_multiple_dbs_to_s3_dag.extract_and_upload_books scheduled__2024-08-03T00:00:00+00:00 [queued]>
[2024-08-04T13:12:12.240+0000] {taskinstance.py:2076} INFO - Dependencies all met for dep_context=requeueable deps ti=<TaskInstance: export_multiple_dbs_to_s3_dag.extract_and_upload_books scheduled__2024-08-03T00:00:00+00:00 [queued]>
[2024-08-04T13:12:12.241+0000] {taskinstance.py:2306} INFO - Starting attempt 1 of 2
[2024-08-04T13:12:12.260+0000] {taskinstance.py:2330} INFO - Executing <Task(PythonOperator): extract_and_upload_books> on 2024-08-03 00:00:00+00:00
[2024-08-04T13:12:12.268+0000] {warnings.py:112} WARNING - /home/***/.local/lib/python3.12/site-packages/***/task/task_runner/standard_task_runner.py:62: DeprecationWarning: This process (pid=72) is multi-threaded, use of fork() may lead to deadlocks in the child.
  pid = os.fork()

[2024-08-04T13:12:12.270+0000] {standard_task_runner.py:64} INFO - Started process 74 to run task
[2024-08-04T13:12:12.270+0000] {standard_task_runner.py:90} INFO - Running: ['***', 'tasks', 'run', 'export_multiple_dbs_to_s3_dag', 'extract_and_upload_books', 'scheduled__2024-08-03T00:00:00+00:00', '--job-id', '263', '--raw', '--subdir', 'DAGS_FOLDER/export_multiple_dbs_to_s3_dag .py', '--cfg-path', '/tmp/tmp5317iurj']
[2024-08-04T13:12:12.271+0000] {standard_task_runner.py:91} INFO - Job 263: Subtask extract_and_upload_books
[2024-08-04T13:12:12.315+0000] {task_command.py:426} INFO - Running <TaskInstance: export_multiple_dbs_to_s3_dag.extract_and_upload_books scheduled__2024-08-03T00:00:00+00:00 [running]> on host 85fb6cf4ba32
[2024-08-04T13:12:12.393+0000] {taskinstance.py:2648} INFO - Exporting env vars: AIRFLOW_CTX_DAG_OWNER='***' AIRFLOW_CTX_DAG_ID='export_multiple_dbs_to_s3_dag' AIRFLOW_CTX_TASK_ID='extract_and_upload_books' AIRFLOW_CTX_EXECUTION_DATE='2024-08-03T00:00:00+00:00' AIRFLOW_CTX_TRY_NUMBER='1' AIRFLOW_CTX_DAG_RUN_ID='scheduled__2024-08-03T00:00:00+00:00'
[2024-08-04T13:12:12.394+0000] {taskinstance.py:430} INFO - ::endgroup::
[2024-08-04T13:12:12.401+0000] {taskinstance.py:441} INFO - ::group::Post task execution logs
[2024-08-04T13:12:12.402+0000] {taskinstance.py:2905} ERROR - Task failed with exception
Traceback (most recent call last):
  File "/home/airflow/.local/lib/python3.12/site-packages/pandas/io/sql.py", line 2262, in execute
    cur.execute(sql, *args)
sqlite3.OperationalError: no such table: Books

The above exception was the direct cause of the following exception:

Traceback (most recent call last):
  File "/home/airflow/.local/lib/python3.12/site-packages/airflow/models/taskinstance.py", line 465, in _execute_task
    result = _execute_callable(context=context, **execute_callable_kwargs)
             ^^^^^^^^^^^^^^^^^^^^^^^^^^^^^^^^^^^^^^^^^^^^^^^^^^^^^^^^^^^^^
  File "/home/airflow/.local/lib/python3.12/site-packages/airflow/models/taskinstance.py", line 432, in _execute_callable
    return execute_callable(context=context, **execute_callable_kwargs)
           ^^^^^^^^^^^^^^^^^^^^^^^^^^^^^^^^^^^^^^^^^^^^^^^^^^^^^^^^^^^^
  File "/home/airflow/.local/lib/python3.12/site-packages/airflow/models/baseoperator.py", line 401, in wrapper
    return func(self, *args, **kwargs)
           ^^^^^^^^^^^^^^^^^^^^^^^^^^^
  File "/home/airflow/.local/lib/python3.12/site-packages/airflow/operators/python.py", line 235, in execute
    return_value = self.execute_callable()
                   ^^^^^^^^^^^^^^^^^^^^^^^
  File "/home/airflow/.local/lib/python3.12/site-packages/airflow/operators/python.py", line 252, in execute_callable
    return self.python_callable(*self.op_args, **self.op_kwargs)
           ^^^^^^^^^^^^^^^^^^^^^^^^^^^^^^^^^^^^^^^^^^^^^^^^^^^^^
  File "/opt/airflow/dags/export_multiple_dbs_to_s3_dag .py", line 31, in extract_and_upload_to_s3
    df = pd.read_sql_query(f"SELECT * FROM {table_name}", conn)
         ^^^^^^^^^^^^^^^^^^^^^^^^^^^^^^^^^^^^^^^^^^^^^^^^^^^^^^
  File "/home/airflow/.local/lib/python3.12/site-packages/pandas/io/sql.py", line 486, in read_sql_query
    return pandas_sql.read_query(
           ^^^^^^^^^^^^^^^^^^^^^^
  File "/home/airflow/.local/lib/python3.12/site-packages/pandas/io/sql.py", line 2326, in read_query
    cursor = self.execute(sql, params)
             ^^^^^^^^^^^^^^^^^^^^^^^^^
  File "/home/airflow/.local/lib/python3.12/site-packages/pandas/io/sql.py", line 2274, in execute
    raise ex from exc
pandas.errors.DatabaseError: Execution failed on sql 'SELECT * FROM Books': no such table: Books
[2024-08-04T13:12:12.413+0000] {taskinstance.py:1206} INFO - Marking task as UP_FOR_RETRY. dag_id=export_multiple_dbs_to_s3_dag, task_id=extract_and_upload_books, run_id=scheduled__2024-08-03T00:00:00+00:00, execution_date=20240803T000000, start_date=20240804T131212, end_date=20240804T131212
[2024-08-04T13:12:12.425+0000] {standard_task_runner.py:110} ERROR - Failed to execute job 263 for task extract_and_upload_books (Execution failed on sql 'SELECT * FROM Books': no such table: Books; 74)
[2024-08-04T13:12:12.444+0000] {local_task_job_runner.py:243} INFO - Task exited with return code 1
[2024-08-04T13:12:12.469+0000] {taskinstance.py:3503} INFO - 0 downstream tasks scheduled from follow-on schedule check
[2024-08-04T13:12:12.471+0000] {local_task_job_runner.py:222} INFO - ::endgroup::
